[32m2024-09-17 12:07:37 +0200[0m - dagster - [34mDEBUG[0m - __ASSET_JOB - de241c68-2257-4a65-b6fc-a7e9c45c5f2d - 82747 - LOGS_CAPTURED - Started capturing logs in process (pid: 82747).
[32m2024-09-17 12:07:37 +0200[0m - dagster - [34mDEBUG[0m - __ASSET_JOB - de241c68-2257-4a65-b6fc-a7e9c45c5f2d - 82747 - ingestion - STEP_START - Started execution of step "ingestion".
[32m2024-09-17 12:07:38 +0200[0m - dagster - [34mERROR[0m - [31m__ASSET_JOB - de241c68-2257-4a65-b6fc-a7e9c45c5f2d - ingestion - Error loading bikes/brands.csv: An error occurred (AccessDenied) when calling the GetObject operation: User: arn:aws:iam::316422555988:user/soda-dagster is not authorized to perform: s3:GetObject on resource: "arn:aws:s3:::soda-dagster/bikes/brands.csv" because no identity-based policy allows the s3:GetObject action[0m
[32m2024-09-17 12:07:38 +0200[0m - dagster - [34mERROR[0m - [31m__ASSET_JOB - de241c68-2257-4a65-b6fc-a7e9c45c5f2d - ingestion - Error loading bikes/categories.csv: An error occurred (AccessDenied) when calling the GetObject operation: User: arn:aws:iam::316422555988:user/soda-dagster is not authorized to perform: s3:GetObject on resource: "arn:aws:s3:::soda-dagster/bikes/categories.csv" because no identity-based policy allows the s3:GetObject action[0m
[32m2024-09-17 12:07:38 +0200[0m - dagster - [34mERROR[0m - [31m__ASSET_JOB - de241c68-2257-4a65-b6fc-a7e9c45c5f2d - ingestion - Error loading bikes/customers.csv: An error occurred (AccessDenied) when calling the GetObject operation: User: arn:aws:iam::316422555988:user/soda-dagster is not authorized to perform: s3:GetObject on resource: "arn:aws:s3:::soda-dagster/bikes/customers.csv" because no identity-based policy allows the s3:GetObject action[0m
[32m2024-09-17 12:07:38 +0200[0m - dagster - [34mERROR[0m - [31m__ASSET_JOB - de241c68-2257-4a65-b6fc-a7e9c45c5f2d - ingestion - Error loading bikes/order_items.csv: An error occurred (AccessDenied) when calling the GetObject operation: User: arn:aws:iam::316422555988:user/soda-dagster is not authorized to perform: s3:GetObject on resource: "arn:aws:s3:::soda-dagster/bikes/order_items.csv" because no identity-based policy allows the s3:GetObject action[0m
[32m2024-09-17 12:07:38 +0200[0m - dagster - [34mERROR[0m - [31m__ASSET_JOB - de241c68-2257-4a65-b6fc-a7e9c45c5f2d - ingestion - Error loading bikes/orders.csv: An error occurred (AccessDenied) when calling the GetObject operation: User: arn:aws:iam::316422555988:user/soda-dagster is not authorized to perform: s3:GetObject on resource: "arn:aws:s3:::soda-dagster/bikes/orders.csv" because no identity-based policy allows the s3:GetObject action[0m
[32m2024-09-17 12:07:38 +0200[0m - dagster - [34mERROR[0m - [31m__ASSET_JOB - de241c68-2257-4a65-b6fc-a7e9c45c5f2d - ingestion - Error loading bikes/products.csv: An error occurred (AccessDenied) when calling the GetObject operation: User: arn:aws:iam::316422555988:user/soda-dagster is not authorized to perform: s3:GetObject on resource: "arn:aws:s3:::soda-dagster/bikes/products.csv" because no identity-based policy allows the s3:GetObject action[0m
[32m2024-09-17 12:07:38 +0200[0m - dagster - [34mERROR[0m - [31m__ASSET_JOB - de241c68-2257-4a65-b6fc-a7e9c45c5f2d - ingestion - Error loading bikes/staffs.csv: An error occurred (AccessDenied) when calling the GetObject operation: User: arn:aws:iam::316422555988:user/soda-dagster is not authorized to perform: s3:GetObject on resource: "arn:aws:s3:::soda-dagster/bikes/staffs.csv" because no identity-based policy allows the s3:GetObject action[0m
[32m2024-09-17 12:07:38 +0200[0m - dagster - [34mERROR[0m - [31m__ASSET_JOB - de241c68-2257-4a65-b6fc-a7e9c45c5f2d - ingestion - Error loading bikes/stocks.csv: An error occurred (AccessDenied) when calling the GetObject operation: User: arn:aws:iam::316422555988:user/soda-dagster is not authorized to perform: s3:GetObject on resource: "arn:aws:s3:::soda-dagster/bikes/stocks.csv" because no identity-based policy allows the s3:GetObject action[0m
[32m2024-09-17 12:07:38 +0200[0m - dagster - [34mERROR[0m - [31m__ASSET_JOB - de241c68-2257-4a65-b6fc-a7e9c45c5f2d - ingestion - Error loading bikes/stores.csv: An error occurred (AccessDenied) when calling the GetObject operation: User: arn:aws:iam::316422555988:user/soda-dagster is not authorized to perform: s3:GetObject on resource: "arn:aws:s3:::soda-dagster/bikes/stores.csv" because no identity-based policy allows the s3:GetObject action[0m
[32m2024-09-17 12:07:38 +0200[0m - dagster - [34mERROR[0m - [31m__ASSET_JOB - de241c68-2257-4a65-b6fc-a7e9c45c5f2d - ingestion - DataFrame missing for index 1. Check if all files are loaded correctly.[0m
[12:07:40] Data source 'soda-dagster' not present in the configuration. Configured data sources: 
[12:07:40] No valid checks found, 0 checks evaluated.
[12:07:40] Data source 'soda-dagster' not present in the configuration. Configured data sources: 
[12:07:40] Data source 'soda-dagster' not present in the configuration. Configured data sources: 
[32m2024-09-17 12:07:40 +0200[0m - dagster - [34mINFO[0m - __ASSET_JOB - de241c68-2257-4a65-b6fc-a7e9c45c5f2d - ingestion - Scan executed successfully.
[32m2024-09-17 12:07:40 +0200[0m - dagster - [34mINFO[0m - __ASSET_JOB - de241c68-2257-4a65-b6fc-a7e9c45c5f2d - ingestion - {'definitionName': 'Soda Dagster Demo', 'defaultDataSource': 'soda-dagster', 'dataTimestamp': '2024-09-17T10:07:38+00:00', 'scanStartTimestamp': '2024-09-17T10:07:38+00:00', 'scanEndTimestamp': '2024-09-17T10:07:40+00:00', 'hasErrors': True, 'hasWarnings': False, 'hasFailures': False, 'metrics': [], 'checks': [], 'checksMetadata': {'count': 0, 'pass': 0, 'warn': 0, 'fail': 0, 'evaluated': 0, 'notEvaluated': 0}, 'queries': [], 'automatedMonitoringChecks': [], 'profiling': [], 'metadata': [], 'logs': [{'level': 'INFO', 'message': 'Soda Library 1.5.21', 'timestamp': '2024-09-17T10:07:38+00:00', 'index': 1, 'doc': None, 'location': None}, {'level': 'INFO', 'message': 'Soda Core 3.0.47', 'timestamp': '2024-09-17T10:07:38+00:00', 'index': 2, 'doc': None, 'location': None}, {'level': 'INFO', 'message': "By downloading and using Soda Library, you agree to Soda's Terms & Conditions (https://go.soda.io/t&c) and Privacy Policy (https://go.soda.io/privacy). ", 'timestamp': '2024-09-17T10:07:38+00:00', 'index': 3, 'doc': None, 'location': None}, {'level': 'ERROR', 'message': "Data source 'soda-dagster' not present in the configuration. Configured data sources: ", 'timestamp': '2024-09-17T10:07:40+00:00', 'index': 4, 'doc': None, 'location': None}, {'level': 'INFO', 'message': 'Scan summary:', 'timestamp': '2024-09-17T10:07:40+00:00', 'index': 5, 'doc': None, 'location': None}, {'level': 'WARNING', 'message': 'No valid checks found, 0 checks evaluated.', 'timestamp': '2024-09-17T10:07:40+00:00', 'index': 6, 'doc': None, 'location': None}, {'level': 'INFO', 'message': '1 errors.', 'timestamp': '2024-09-17T10:07:40+00:00', 'index': 7, 'doc': None, 'location': None}, {'level': 'INFO', 'message': 'Oops! 1 error. 0 failures. 0 warnings. 0 pass.', 'timestamp': '2024-09-17T10:07:40+00:00', 'index': 8, 'doc': None, 'location': None}, {'level': 'INFO', 'message': 'Sending results to Soda Cloud', 'timestamp': '2024-09-17T10:07:40+00:00', 'index': 9, 'doc': None, 'location': None}, {'level': 'ERROR', 'message': "Data source 'soda-dagster' not present in the configuration. Configured data sources: ", 'timestamp': '2024-09-17T10:07:40+00:00', 'index': 10, 'doc': None, 'location': None}, {'level': 'INFO', 'message': 'Soda Cloud Trace: 5601995205909750339', 'timestamp': '2024-09-17T10:07:40+00:00', 'index': 11, 'doc': None, 'location': None}]}
[32m2024-09-17 12:07:40 +0200[0m - dagster - [34mINFO[0m - __ASSET_JOB - de241c68-2257-4a65-b6fc-a7e9c45c5f2d - ingestion - INFO   | Soda Library 1.5.21
INFO   | Soda Core 3.0.47
INFO   | By downloading and using Soda Library, you agree to Soda's Terms & Conditions (https://go.soda.io/t&c) and Privacy Policy (https://go.soda.io/privacy). 
ERROR  | Data source 'soda-dagster' not present in the configuration. Configured data sources: 
INFO   | Scan summary:
WARNING| No valid checks found, 0 checks evaluated.
INFO   | 1 errors.
INFO   | Oops! 1 error. 0 failures. 0 warnings. 0 pass.
INFO   | Sending results to Soda Cloud
ERROR  | Data source 'soda-dagster' not present in the configuration. Configured data sources: 
INFO   | Soda Cloud Trace: 5601995205909750339
[32m2024-09-17 12:07:40 +0200[0m - dagster - [34mERROR[0m - [31m__ASSET_JOB - de241c68-2257-4a65-b6fc-a7e9c45c5f2d - 82747 - ingestion - STEP_FAILURE - Execution of step "ingestion" failed.

dagster._core.errors.DagsterInvariantViolationError: op "ingestion" has multiple outputs, but only one output was returned of type <class 'dagster._core.definitions.events.Output'>. When using multiple outputs, either yield each output, or return a tuple containing a value for each output. Check out the documentation on outputs for more: https://docs.dagster.io/concepts/ops-jobs-graphs/ops#outputs.

Stack Trace:
  File "/Users/hazem/Documents/Soda/GitHub/soda-dagster-demo/.venv/lib/python3.9/site-packages/dagster/_core/execution/plan/execute_plan.py", line 282, in dagster_event_sequence_for_step
    for step_event in check.generator(step_events):
  File "/Users/hazem/Documents/Soda/GitHub/soda-dagster-demo/.venv/lib/python3.9/site-packages/dagster/_core/execution/plan/execute_step.py", line 494, in core_dagster_event_sequence_for_step
    for user_event in _step_output_error_checked_user_event_sequence(
  File "/Users/hazem/Documents/Soda/GitHub/soda-dagster-demo/.venv/lib/python3.9/site-packages/dagster/_core/execution/plan/execute_step.py", line 183, in _step_output_error_checked_user_event_sequence
    for user_event in user_event_sequence:
  File "/Users/hazem/Documents/Soda/GitHub/soda-dagster-demo/.venv/lib/python3.9/site-packages/dagster/_core/execution/plan/execute_step.py", line 88, in _process_asset_results_to_events
    for user_event in user_event_sequence:
  File "/Users/hazem/Documents/Soda/GitHub/soda-dagster-demo/.venv/lib/python3.9/site-packages/dagster/_core/execution/plan/compute.py", line 198, in execute_core_compute
    for step_output in _yield_compute_results(step_context, inputs, compute_fn, compute_context):
  File "/Users/hazem/Documents/Soda/GitHub/soda-dagster-demo/.venv/lib/python3.9/site-packages/dagster/_core/execution/plan/compute.py", line 167, in _yield_compute_results
    for event in iterate_with_context(
  File "/Users/hazem/Documents/Soda/GitHub/soda-dagster-demo/.venv/lib/python3.9/site-packages/dagster/_utils/__init__.py", line 473, in iterate_with_context
    next_output = next(iterator)
  File "/Users/hazem/Documents/Soda/GitHub/soda-dagster-demo/.venv/lib/python3.9/site-packages/dagster/_core/execution/plan/compute_generator.py", line 144, in _coerce_op_compute_fn_to_iterator
    for event in validate_and_coerce_op_result_to_iterator(result, context, output_defs):
  File "/Users/hazem/Documents/Soda/GitHub/soda-dagster-demo/.venv/lib/python3.9/site-packages/dagster/_core/execution/plan/compute_generator.py", line 310, in validate_and_coerce_op_result_to_iterator
    for position, output_def, element in _zip_and_iterate_op_result(
  File "/Users/hazem/Documents/Soda/GitHub/soda-dagster-demo/.venv/lib/python3.9/site-packages/dagster/_core/execution/plan/compute_generator.py", line 166, in _zip_and_iterate_op_result
    result = _validate_multi_return(context, result, expected_return_outputs)
  File "/Users/hazem/Documents/Soda/GitHub/soda-dagster-demo/.venv/lib/python3.9/site-packages/dagster/_core/execution/plan/compute_generator.py", line 220, in _validate_multi_return
    raise DagsterInvariantViolationError(
[0m
