[32m2024-09-17 16:59:44 +0200[0m - dagster - [34mDEBUG[0m - staging_pipeline - 7f23342e-c29f-40e1-bbd7-5da0be05d447 - 95832 - LOGS_CAPTURED - Started capturing logs in process (pid: 95832).
[32m2024-09-17 16:59:44 +0200[0m - dagster - [34mDEBUG[0m - staging_pipeline - 7f23342e-c29f-40e1-bbd7-5da0be05d447 - 95832 - soda_UI_check - STEP_START - Started execution of step "soda_UI_check".
[32m2024-09-17 16:59:44 +0200[0m - dagster - [34mINFO[0m - staging_pipeline - 7f23342e-c29f-40e1-bbd7-5da0be05d447 - soda_UI_check - Request successful
[32m2024-09-17 16:59:54 +0200[0m - dagster - [34mINFO[0m - staging_pipeline - 7f23342e-c29f-40e1-bbd7-5da0be05d447 - soda_UI_check - Scan failed with status: completedWithErrors
[32m2024-09-17 16:59:54 +0200[0m - dagster - [34mERROR[0m - [31mstaging_pipeline - 7f23342e-c29f-40e1-bbd7-5da0be05d447 - 95832 - soda_UI_check - STEP_FAILURE - Execution of step "soda_UI_check" failed.

dagster._core.errors.DagsterInvariantViolationError: op "soda_UI_check" has multiple outputs, but only one output was returned of type <class 'list'>. When using multiple outputs, either yield each output, or return a tuple containing a value for each output. Check out the documentation on outputs for more: https://docs.dagster.io/concepts/ops-jobs-graphs/ops#outputs.

Stack Trace:
  File "/Users/hazem/Documents/Soda/GitHub/soda-dagster-demo/.venv/lib/python3.9/site-packages/dagster/_core/execution/plan/execute_plan.py", line 282, in dagster_event_sequence_for_step
    for step_event in check.generator(step_events):
  File "/Users/hazem/Documents/Soda/GitHub/soda-dagster-demo/.venv/lib/python3.9/site-packages/dagster/_core/execution/plan/execute_step.py", line 494, in core_dagster_event_sequence_for_step
    for user_event in _step_output_error_checked_user_event_sequence(
  File "/Users/hazem/Documents/Soda/GitHub/soda-dagster-demo/.venv/lib/python3.9/site-packages/dagster/_core/execution/plan/execute_step.py", line 183, in _step_output_error_checked_user_event_sequence
    for user_event in user_event_sequence:
  File "/Users/hazem/Documents/Soda/GitHub/soda-dagster-demo/.venv/lib/python3.9/site-packages/dagster/_core/execution/plan/execute_step.py", line 88, in _process_asset_results_to_events
    for user_event in user_event_sequence:
  File "/Users/hazem/Documents/Soda/GitHub/soda-dagster-demo/.venv/lib/python3.9/site-packages/dagster/_core/execution/plan/compute.py", line 198, in execute_core_compute
    for step_output in _yield_compute_results(step_context, inputs, compute_fn, compute_context):
  File "/Users/hazem/Documents/Soda/GitHub/soda-dagster-demo/.venv/lib/python3.9/site-packages/dagster/_core/execution/plan/compute.py", line 167, in _yield_compute_results
    for event in iterate_with_context(
  File "/Users/hazem/Documents/Soda/GitHub/soda-dagster-demo/.venv/lib/python3.9/site-packages/dagster/_utils/__init__.py", line 473, in iterate_with_context
    next_output = next(iterator)
  File "/Users/hazem/Documents/Soda/GitHub/soda-dagster-demo/.venv/lib/python3.9/site-packages/dagster/_core/execution/plan/compute_generator.py", line 144, in _coerce_op_compute_fn_to_iterator
    for event in validate_and_coerce_op_result_to_iterator(result, context, output_defs):
  File "/Users/hazem/Documents/Soda/GitHub/soda-dagster-demo/.venv/lib/python3.9/site-packages/dagster/_core/execution/plan/compute_generator.py", line 310, in validate_and_coerce_op_result_to_iterator
    for position, output_def, element in _zip_and_iterate_op_result(
  File "/Users/hazem/Documents/Soda/GitHub/soda-dagster-demo/.venv/lib/python3.9/site-packages/dagster/_core/execution/plan/compute_generator.py", line 166, in _zip_and_iterate_op_result
    result = _validate_multi_return(context, result, expected_return_outputs)
  File "/Users/hazem/Documents/Soda/GitHub/soda-dagster-demo/.venv/lib/python3.9/site-packages/dagster/_core/execution/plan/compute_generator.py", line 220, in _validate_multi_return
    raise DagsterInvariantViolationError(
[0m
