[32m2024-09-24 20:41:57 +0200[0m - dagster - [34mDEBUG[0m - staging_pipeline - 16c9ea67-ba0a-406e-8e8d-c0e3563ba633 - 46109 - LOGS_CAPTURED - Started capturing logs in process (pid: 46109).
[32m2024-09-24 20:41:57 +0200[0m - dagster - [34mDEBUG[0m - staging_pipeline - 16c9ea67-ba0a-406e-8e8d-c0e3563ba633 - 46109 - dbt_staging - STEP_START - Started execution of step "dbt_staging".
[32m2024-09-24 20:41:57 +0200[0m - dagster - [34mINFO[0m - staging_pipeline - 16c9ea67-ba0a-406e-8e8d-c0e3563ba633 - dbt_staging - A dbt subsetted execution is not being performed. Using the default dbt selection arguments `['--select', 'marts']`.
[32m2024-09-24 20:41:57 +0200[0m - dagster - [34mINFO[0m - staging_pipeline - 16c9ea67-ba0a-406e-8e8d-c0e3563ba633 - dbt_staging - Copying `/Users/hazem/Documents/Soda/GitHub/soda-dagster-demo/dbt-project/target/partial_parse.msgpack` to `/Users/hazem/Documents/Soda/GitHub/soda-dagster-demo/dbt-project/target/dbt_staging-16c9ea6-b038560/partial_parse.msgpack` to take advantage of partial parsing.
[32m2024-09-24 20:41:57 +0200[0m - dagster - [34mINFO[0m - staging_pipeline - 16c9ea67-ba0a-406e-8e8d-c0e3563ba633 - dbt_staging - Running dbt command: `dbt build --select marts`.
[32m2024-09-24 20:42:03 +0200[0m - dagster - [34mINFO[0m - staging_pipeline - 16c9ea67-ba0a-406e-8e8d-c0e3563ba633 - dbt_staging - Finished dbt command: `dbt build --select marts`.
[32m2024-09-24 20:42:03 +0200[0m - dagster - [34mERROR[0m - [31mstaging_pipeline - 16c9ea67-ba0a-406e-8e8d-c0e3563ba633 - 46109 - dbt_staging - STEP_FAILURE - Execution of step "dbt_staging" failed.

dagster_dbt.errors.DagsterDbtCliRuntimeError: The dbt CLI process with command

`dbt build --select marts`

failed with exit code `2`. Check the stdout in the Dagster compute logs for the full information about the error, or view the dbt debug log: /Users/hazem/Documents/Soda/GitHub/soda-dagster-demo/dbt-project/target/dbt_staging-16c9ea6-b038560/dbt.log.

Errors parsed from dbt logs:

Encountered an error:
Database Error
  ('communication error', ConnectionResetError(54, 'Connection reset by peer'))

Stack Trace:
  File "/Users/hazem/Documents/Soda/GitHub/soda-dagster-demo/.venv/lib/python3.9/site-packages/dagster/_core/execution/plan/execute_plan.py", line 282, in dagster_event_sequence_for_step
    for step_event in check.generator(step_events):
  File "/Users/hazem/Documents/Soda/GitHub/soda-dagster-demo/.venv/lib/python3.9/site-packages/dagster/_core/execution/plan/execute_step.py", line 494, in core_dagster_event_sequence_for_step
    for user_event in _step_output_error_checked_user_event_sequence(
  File "/Users/hazem/Documents/Soda/GitHub/soda-dagster-demo/.venv/lib/python3.9/site-packages/dagster/_core/execution/plan/execute_step.py", line 183, in _step_output_error_checked_user_event_sequence
    for user_event in user_event_sequence:
  File "/Users/hazem/Documents/Soda/GitHub/soda-dagster-demo/.venv/lib/python3.9/site-packages/dagster/_core/execution/plan/execute_step.py", line 88, in _process_asset_results_to_events
    for user_event in user_event_sequence:
  File "/Users/hazem/Documents/Soda/GitHub/soda-dagster-demo/.venv/lib/python3.9/site-packages/dagster/_core/execution/plan/compute.py", line 198, in execute_core_compute
    for step_output in _yield_compute_results(step_context, inputs, compute_fn, compute_context):
  File "/Users/hazem/Documents/Soda/GitHub/soda-dagster-demo/.venv/lib/python3.9/site-packages/dagster/_core/execution/plan/compute.py", line 167, in _yield_compute_results
    for event in iterate_with_context(
  File "/Users/hazem/Documents/Soda/GitHub/soda-dagster-demo/.venv/lib/python3.9/site-packages/dagster/_utils/__init__.py", line 473, in iterate_with_context
    next_output = next(iterator)
  File "/Users/hazem/Documents/Soda/GitHub/soda-dagster-demo/dbt-project/dagster/pipeline/assets.py", line 765, in dbt_staging
    yield from dbt.cli(["build"],context=context, manifest=dagsteretl_project.manifest_path).stream()
  File "/Users/hazem/Documents/Soda/GitHub/soda-dagster-demo/.venv/lib/python3.9/site-packages/dagster_dbt/core/dbt_event_iterator.py", line 203, in __next__
    return next(self._inner_iterator)
  File "/Users/hazem/Documents/Soda/GitHub/soda-dagster-demo/.venv/lib/python3.9/site-packages/dagster_dbt/core/dbt_cli_invocation.py", line 269, in _stream_asset_events
    for event in self.stream_raw_events():
  File "/Users/hazem/Documents/Soda/GitHub/soda-dagster-demo/.venv/lib/python3.9/site-packages/dagster_dbt/core/dbt_cli_invocation.py", line 362, in stream_raw_events
    self._raise_on_error()
  File "/Users/hazem/Documents/Soda/GitHub/soda-dagster-demo/.venv/lib/python3.9/site-packages/dagster_dbt/core/dbt_cli_invocation.py", line 454, in _raise_on_error
    raise error
[0m
